<mujoco model="robot_hand_sim">
<!--    <compiler angle="radian" meshdir="/home/kavin/Documents/RosProjects/robot_ws/src/robot_hand_sim/meshes/" />-->
<!--    <size njmax="500" nconmax="100" />-->
    <compiler angle="radian"
          inertiafromgeom="true"
          texturedir="textures/"
          meshdir="/home/kavin/Documents/RosProjects/robot_ws/src/robot_hand_sim/meshes/"/>
    <option timestep="2e-3"
            iterations="100"
            tolerance="1e-10"
            impratio="100"/>

    <default class="robot_sim">
        <material specular="0.5" shininess="0.25"/>
        <joint armature="0.1" limited="true"/>
        <general dyntype="none" biastype="affine" ctrlrange="-2.8973 2.8973"/>
        <geom density="5.0"  />
        <default class="neck">
            <joint axis="0 0 -1" range="-3.14 3.14" damping="2"/>
            <position ctrlrange="-1.57 1.57"/>
        </default>
        <default class="head">
            <joint axis="-1 0 0" range="-3.14 3.14" damping="2"/>
            <position ctrlrange="-0.3 0.3"/>
        </default>
        <default class="shoulder_1">
            <joint axis="1 0 0" range="-3.14 3.14" damping="2"/>
            <position ctrlrange="-3.14 3.14"/>
        </default>
        <default class="shoulder_2">
            <joint axis="0 1 0" range="-3.14 3.14" damping="2"/>
            <position ctrlrange="-1.57 1.57"/>
        </default>
        <default class="shoulder_3">
            <joint axis="1 0 0" range="-3.14 3.14" damping="1"/>
            <position ctrlrange="-2 2"/>
        </default>
        <default class="elbow">
            <joint axis="0 0 -1" range="-3.14 3.14" damping="1"/>
            <position ctrlrange="-1.57 1.57"/>
        </default>
        <default class="wrist_1">
            <joint axis="1 0 0" range="-3.14 3.14" damping="1"/>
            <position ctrlrange="-3.14 3.14"/>
        </default>
        <default class="wrist_2">
            <joint axis="0 0 -1" range="-3.14 3.14" damping="1"/>
            <position ctrlrange="-1.57 1.57"/>
        </default>
        <default class="wrist_3">
            <joint axis="-1 0 0" range="-3.14 3.14" damping="1"/>
            <position ctrlrange="-3.14 3.14"/>
        </default>

        <default class="thumb_1">
            <joint axis="1 0 0" range="-3.14 3.14" damping="1"/>
            <position ctrlrange="-3.14 3.14"/>
        </default>
        <default class="thumb_2">
            <joint axis="-1 0 0" range="-3.14 3.14" damping="1"/>
            <position ctrlrange="-3.14 3.14"/>
        </default>
        <default class="thumb_3">
            <joint axis="1 0 0" range="-3.14 3.14" damping="1"/>
            <position ctrlrange="-1.57 1.57"/>
        </default>
        <default class="thumb_4">
            <joint axis="-1 0 0" range="-3.14 3.14" damping="1"/>
            <position ctrlrange="0.7 2"/>
        </default>
        <default class="finger_1">
            <joint axis="-1 0 0" range="-3.14 3.14" damping="1"/>
            <position ctrlrange="-1 1"/>
        </default>
        <default class="finger_2">
            <joint axis="1 0 0" range="-3.14 3.14" damping="1"/>
            <position ctrlrange="-1.57 1.57"/>
        </default>
        <default class="finger_3">
            <joint axis="-1 0 0" range="-3.14 3.14" damping="1"/>
            <position ctrlrange="-1 1"/>
        </default>
        <default class="visual">
            <geom type="mesh" contype="0" conaffinity="0" group="0" material="dark"/>
        </default>
    </default>

    <asset>
        <texture builtin="gradient" height="100" rgb1=".4 .5 .6" rgb2="0 0 0" type="skybox" width="100"/>
        <texture name="texplane" type="2d" builtin="checker" rgb1=".2 .3 .4" rgb2=".1 0.15 0.2" width="100" height="100" />
        <material name="MatPlane" reflectance="0.5" texture="texplane" texrepeat="1 1" texuniform="true" />
        <material name="dark" specular="0" shininess="0.25" rgba="0.2 0.2 0.2 1"/>


        <mesh name="body" file="body_old.STL" />
        <mesh name="neck" file="neck.STL" />
        <mesh name="head" file="head.STL" />
        <mesh name="left_1" file="left_1.STL" />
        <mesh name="left_2" file="left_2.STL" />
        <mesh name="left_3" file="left_3.STL" />
        <mesh name="left_4" file="left_4.STL" />
        <mesh name="left_5" file="left_5.STL" />
        <mesh name="left_6" file="left_6.STL" />
        <mesh name="left_7" file="left_7.STL" />
        <mesh name="left_11" file="left_11.STL" />
        <mesh name="left_12" file="left_12.STL" />
        <mesh name="left_13" file="left_13.STL" />
        <mesh name="left_14" file="left_14.STL" />
        <mesh name="left_21" file="left_21.STL" />
        <mesh name="left_22" file="left_22.STL" />
        <mesh name="left_23" file="left_23.STL" />
        <mesh name="left_31" file="left_31.STL" />
        <mesh name="left_32" file="left_32.STL" />
        <mesh name="left_33" file="left_33.STL" />
        <mesh name="left_41" file="left_41.STL" />
        <mesh name="left_42" file="left_42.STL" />
        <mesh name="left_43" file="left_43.STL" />
        <mesh name="left_51" file="left_51.STL" />
        <mesh name="left_52" file="left_52.STL" />
        <mesh name="left_53" file="left_53.STL" />
        <mesh name="right_1" file="right_1.STL" />
        <mesh name="right_2" file="right_2.STL" />
        <mesh name="right_3" file="right_3.STL" />
        <mesh name="right_4" file="right_4.STL" />
        <mesh name="right_5" file="right_5.STL" />
        <mesh name="right_6" file="right_6.STL" />
        <mesh name="right_7" file="right_7.STL" />
        <mesh name="right_11" file="right_11.STL" />
        <mesh name="right_12" file="right_12.STL" />
        <mesh name="right_13" file="right_13.STL" />
        <mesh name="right_14" file="right_14.STL" />
        <mesh name="right_21" file="right_21.STL" />
        <mesh name="right_22" file="right_22.STL" />
        <mesh name="right_23" file="right_23.STL" />
        <mesh name="right_31" file="right_31.STL" />
        <mesh name="right_32" file="right_32.STL" />
        <mesh name="right_33" file="right_33.STL" />
        <mesh name="right_41" file="right_41.STL" />
        <mesh name="right_42" file="right_42.STL" />
        <mesh name="right_43" file="right_43.STL" />
        <mesh name="right_51" file="right_51.STL" />
        <mesh name="right_52" file="right_52.STL" />
        <mesh name="right_53" file="right_53.STL" />
    </asset>
    <worldbody>
        <geom name="floor" pos="0 0 0" size="10 10 0.125" type="plane" material="MatPlane" condim="3" group="2" rgba="0.8 0.9 0.8 1" />
        <light cutoff="100" diffuse="1 1 1" dir="-0 0 -1.3" directional="true" exponent="1" pos="0 0 1.3" specular=".1 .1 .1" castshadow="false"/>

        <body name="body" pos="0 0 0." childclass="robot_sim">
            <inertial pos="0 0 0" quat="0.5 0.5 -0.5 0.5" mass="4" diaginertia="0.0072 0.00443333 0.00443333" />
            <geom quat="0 0 0 1" type="mesh" contype="0" conaffinity="0" group="1" rgba="0.792157 0.819608 0.933333 1" mesh="body" />
            <geom quat="0 0 0 1" type="mesh" rgba="0.792157 0.819608 0.933333 1" mesh="body" />
            <body name="left_1" pos="0.13751 -0.00843684 0.43" quat="0.0396236 0.0478647 0.768815 0.636445">
                <inertial pos="-0.0389123 -8.15099e-11 4.37583e-11" quat="0.707107 0 0 0.707107" mass="0.450915" diaginertia="0.00114268 0.000950117 0.000939472" />
                <joint class="shoulder_1" name="left_j1"/>
                <geom class="visual" mesh="left_1"/>
<!--                <geom type="mesh" rgba="0.792157 0.819608 0.933333 1" mesh="left_1" />-->
                <body name="left_2" pos="-0.075 0 0" quat="0.934135 0 -0.356919 0">
                    <inertial pos="-0.0621308 1.25597e-07 0.00042437" quat="3.21075e-06 0.706526 3.20548e-06 0.707688" mass="1.56019" diaginertia="0.00710312 0.00597558 0.00259922" />
                    <joint class="shoulder_2" name="left_j2" />
                    <geom type="mesh" contype="0" conaffinity="0" group="1" rgba="0.792157 0.819608 0.933333 1" mesh="left_2" />
                    <geom type="mesh" rgba="0.792157 0.819608 0.933333 1" mesh="left_2" />
                    <body name="left_3" pos="-0.16 0 0" quat="0.792164 0.610309 0 0">
                        <inertial pos="-0.059665 2.14069e-07 -0.000729859" quat="0.502955 0.497027 0.497027 0.502955" mass="0.52034" diaginertia="0.00128574 0.00107323 0.000678269" />
                        <joint class="shoulder_3" name="left_j3" />
                        <geom type="mesh" contype="0" conaffinity="0" group="1" rgba="0.792157 0.819608 0.933333 1" mesh="left_3" />
                        <geom type="mesh" rgba="0.792157 0.819608 0.933333 1" mesh="left_3" />
                        <body name="left_4" pos="-0.121 0 0.037" quat="0.854814 0 0 0.518935">
                            <inertial pos="-0.0236502 -1.38379e-09 -0.037" quat="0.5 0.5 0.5 0.5" mass="0.187003" diaginertia="0.000176801 0.00013087 0.000111406" />
                            <joint class="elbow" name="left_j4"/>
                            <geom type="mesh" contype="0" conaffinity="0" group="1" rgba="0.792157 0.819608 0.933333 1" mesh="left_4" />
                            <geom type="mesh" rgba="0.792157 0.819608 0.933333 1" mesh="left_4" />
                            <body name="left_5" pos="-0.058 0 -0.037" quat="0.184654 -0.982804 0 0">
                                <inertial pos="-0.118694 -2.89295e-08 1.30138e-07" quat="0.499999 0.500001 0.500001 0.499999" mass="1.41911" diaginertia="0.00746362 0.00730999 0.00143555" />
                                <joint class="wrist_1" name="left_j5" />
                                <geom type="mesh" contype="0" conaffinity="0" group="1" rgba="0.792157 0.819608 0.933333 1" mesh="left_5" />
                                <geom type="mesh" rgba="0.792157 0.819608 0.933333 1" mesh="left_5" />
                                <body name="left_6" pos="-0.250811 0 0.025" quat="0.108969 0 0 0.994045">
                                    <inertial pos="0.00125752 -0.0001315 -0.0250062" quat="0.036822 0.70613 -0.0368186 0.706165" mass="0.130726" diaginertia="6.86601e-05 5.37786e-05 4.85598e-05" />
                                    <joint class="wrist_2" name="left_j6"/>
                                    <geom type="mesh" contype="0" conaffinity="0" group="1" rgba="0.792157 0.819608 0.933333 1" mesh="left_6" />
                                    <geom type="mesh" rgba="0.792157 0.819608 0.933333 1" mesh="left_6" />
                                    <body name="left_7" pos="0.0397831 -0.00416024 -0.025" quat="0.0520458 -0.00170134 -0.0326275 0.99811">
                                        <inertial pos="-0.0460103 -2.70526e-06 -0.00209832" quat="0.526839 0.471542 0.47162 0.526938" mass="0.128554" diaginertia="0.000143165 0.00010397 5.04883e-05" />
                                        <joint class="wrist_3" name="left_j7" />
                                        <geom type="mesh" contype="0" conaffinity="0" group="1" rgba="0.792157 0.819608 0.933333 1" mesh="left_7" />
                                        <geom type="mesh" rgba="0.792157 0.819608 0.933333 1" mesh="left_7" />
                                        <body name="left_11" pos="-0.0418541 0 0.0331562" quat="0.761558 -0.580964 -0.228378 -0.174221">
                                            <inertial pos="-1.20204e-12 -2.29261e-11 0.00296384" quat="0.707107 0 0 0.707107" mass="0.00158261" diaginertia="6.47978e-08 5.66929e-08 5.56708e-08" />
                                            <joint class="thumb_1" name="left_f1_j1" />
                                            <geom type="mesh" contype="0" conaffinity="0" group="1" rgba="0.792157 0.819608 0.933333 1" mesh="left_11" />
<!--                                            <geom type="mesh" rgba="0.792157 0.819608 0.933333 1" mesh="left_11" />-->
                                            <body name="left_12" pos="0 0 0.005" quat="0.199438 0.678398 -0.199438 0.678398">
                                                <inertial pos="0.00925016 2.66269e-10 -2.89533e-10" quat="0.5 0.5 0.5 0.5" mass="0.00237615" diaginertia="1.18675e-07 1.15819e-07 1.06634e-07" />
                                                <joint class="thumb_2" name="left_f1_j2" />
                                                <geom type="mesh" contype="0" conaffinity="0" group="1" rgba="0.792157 0.819608 0.933333 1" mesh="left_12" />
<!--                                                <geom type="mesh" rgba="0.792157 0.819608 0.933333 1" mesh="left_12" />-->
                                                <body name="left_13" pos="0.0163204 -0.000360412 0" quat="0.699349 0.104454 0.699349 -0.104454">
                                                    <inertial pos="-3.19965e-08 -2.5141e-07 0.0147548" quat="0.706869 4.57235e-06 -4.57543e-06 0.707345" mass="0.00477507" diaginertia="5.13037e-07 5.06539e-07 1.11818e-07" />
                                                    <joint class="thumb_3" name="left_f1_j3"/>
                                                    <geom type="mesh" contype="0" conaffinity="0" group="1" rgba="0.792157 0.819608 0.933333 1" mesh="left_13" />
                                                    <geom type="mesh" rgba="0.792157 0.819608 0.933333 1" mesh="left_13" />
                                                    <body name="left_14" pos="0.0045 0 0.0282335" quat="0 0 0.431781 0.901979">
                                                        <inertial pos="0.00451258 -0.000148506 0.0147394" quat="0.70471 0.00742834 -0.00610739 0.70943" mass="0.00459561" diaginertia="3.58607e-07 3.47268e-07 1.55217e-07" />
                                                        <joint class="thumb_4" name="left_f1_j4" />
                                                        <geom type="mesh" contype="0" conaffinity="0" group="1" rgba="0.792157 0.819608 0.933333 1" mesh="left_14" />
                                                        <geom type="mesh" rgba="0.792157 0.819608 0.933333 1" mesh="left_14" />
                                                    </body>
                                                </body>
                                            </body>
                                        </body>
                                        <body name="left_21" pos="-0.098215 -0.0010783 0.023314" quat="0.777412 0.201415 -0.576826 0.149446">
                                            <inertial pos="3.3671e-08 0.0147548 -2.43413e-07" quat="0.500171 0.500165 -0.499829 0.499835" mass="0.00477507" diaginertia="5.13036e-07 5.06539e-07 1.11818e-07" />
                                            <joint class="finger_1" name="left_f2_j1" />
                                            <geom type="mesh" contype="0" conaffinity="0" group="1" rgba="0.792157 0.819608 0.933333 1" mesh="left_21" />
                                            <geom type="mesh" rgba="0.792157 0.819608 0.933333 1" mesh="left_21" />
                                            <body name="left_22" pos="0.0045 0.028233 0" quat="-1.17061e-06 -3.48168e-06 -0.947859 -0.318689">
                                                <inertial pos="0.0045 0 0.0105" mass="0.00239726" diaginertia="1.69655e-07 1.65763e-07 9.58619e-08" />
                                                <joint class="finger_2" name="left_f2_j2" />
                                                <geom type="mesh" contype="0" conaffinity="0" group="1" rgba="0.792157 0.819608 0.933333 1" mesh="left_22" />
                                                <geom type="mesh" rgba="0.792157 0.819608 0.933333 1" mesh="left_22" />
                                                <body name="left_23" pos="0.0045 0.00018802 0.019598" quat="-2.76456e-06 -2.4186e-06 -0.658444 -0.752629">
                                                    <inertial pos="-1.84261e-05 0.0106328 -3.04923e-05" quat="0.495099 0.49578 -0.503347 0.505688" mass="0.00351082" diaginertia="2.40713e-07 2.34317e-07 7.61094e-08" />
                                                    <joint class="finger_3" name="left_f2_j3" />
                                                    <geom type="mesh" contype="0" conaffinity="0" group="1" rgba="0.792157 0.819608 0.933333 1" mesh="left_23" />
                                                    <geom type="mesh" rgba="0.792157 0.819608 0.933333 1" mesh="left_23" />
                                                </body>
                                            </body>
                                        </body>
                                        <body name="left_31" pos="-0.101315 -0.00115735 0.00328499" quat="0.698993 0.106812 -0.698993 0.106812">
                                            <inertial pos="3.45537e-08 0.0147121 2.33024e-07" quat="0.499837 0.499831 -0.500163 0.500169" mass="0.00477507" diaginertia="5.13037e-07 5.06539e-07 1.11818e-07" />
                                            <joint class="finger_1" name="left_f3_j1" />
                                            <geom type="mesh" contype="0" conaffinity="0" group="1" rgba="0.792157 0.819608 0.933333 1" mesh="left_31" />
                                            <geom type="mesh" rgba="0.792157 0.819608 0.933333 1" mesh="left_31" />
                                            <body name="left_32" pos="0.0045 0.0282335 0" quat="0 0 -0.89336 -0.449341">
                                                <inertial pos="0.0045 1.59006e-12 0.0125" mass="0.00316954" diaginertia="2.43247e-07 2.35819e-07 1.2078e-07" />
                                                <joint class="finger_2" name="left_f3_j2" />
                                                <geom type="mesh" contype="0" conaffinity="0" group="1" rgba="0.792157 0.819608 0.933333 1" mesh="left_32" />
                                                <geom type="mesh" rgba="0.792157 0.819608 0.933333 1" mesh="left_32" />
                                                <body name="left_33" pos="0.0045 0.00105534 0.0240578" quat="0 0 -0.952649 -0.304071">
                                                    <inertial pos="-1.96597e-05 -0.00278683 -0.0120912" quat="0.696291 -0.0778459 0.0810783 0.708904" mass="0.0040794" diaginertia="3.44988e-07 3.37593e-07 9.02119e-08" />
                                                    <joint class="finger_3" name="left_f3_j3" />
                                                    <geom type="mesh" contype="0" conaffinity="0" group="1" rgba="0.792157 0.819608 0.933333 1" mesh="left_33" />
                                                    <geom type="mesh" rgba="0.792157 0.819608 0.933333 1" mesh="left_33" />
                                                </body>
                                            </body>
                                        </body>
                                        <body name="left_41" pos="-0.0993768 -0.00111217 -0.0159741" quat="-0.618804 -0.140723 0.753597 -0.171376">
                                            <inertial pos="3.5256e-07 0.014712 -1.29384e-07" quat="0.499578 0.499586 -0.500417 0.500418" mass="0.0047752" diaginertia="5.13055e-07 5.06525e-07 1.11822e-07" />
                                            <joint class="finger_1" name="left_f4_j1" />
                                            <geom type="mesh" contype="0" conaffinity="0" group="1" rgba="0.792157 0.819608 0.933333 1" mesh="left_41" />
                                            <geom type="mesh" rgba="0.792157 0.819608 0.933333 1" mesh="left_41" />
                                            <body name="left_42" pos="0.0045 0.0282335 0" quat="0 0 0.882414 0.470473">
                                                <inertial pos="0.0045 3.16885e-12 0.011" mass="0.00259033" diaginertia="1.86013e-07 1.81238e-07 1.02092e-07" />
                                                <joint class="finger_2" name="left_f4_j2" />
                                                <geom type="mesh" contype="0" conaffinity="0" group="1" rgba="0.792157 0.819608 0.933333 1" mesh="left_42" />
                                                <geom type="mesh" rgba="0.792157 0.819608 0.933333 1" mesh="left_42" />
                                                <body name="left_43" pos="0.0045 0.00126628 0.0213692" quat="0 0 0.229037 0.973418">
                                                    <inertial pos="-1.83581e-05 0.0106328 -3.0425e-05" quat="0.495051 0.495733 -0.503395 0.505734" mass="0.00351084" diaginertia="2.40711e-07 2.34319e-07 7.61093e-08" />
                                                    <joint class="finger_3" name="left_f4_j3" />
                                                    <geom type="mesh" contype="0" conaffinity="0" group="1" rgba="0.792157 0.819608 0.933333 1" mesh="left_43" />
                                                    <geom type="mesh" rgba="0.792157 0.819608 0.933333 1" mesh="left_43" />
                                                </body>
                                            </body>
                                        </body>
                                        <body name="left_51" pos="-0.095232 -0.00100058 -0.0323468" quat="-0.57094 -0.184341 0.761329 -0.245813">
                                            <inertial pos="-1.44392e-08 0.0147121 -2.39394e-07" quat="0.499813 0.49982 -0.500186 0.50018" mass="0.00477507" diaginertia="5.13037e-07 5.06539e-07 1.11818e-07" />
                                            <joint class="finger_1" name="left_f5_j1" />
                                            <geom type="mesh" contype="0" conaffinity="0" group="1" rgba="0.792157 0.819608 0.933333 1" mesh="left_51" />
                                            <geom type="mesh" rgba="0.792157 0.819608 0.933333 1" mesh="left_51" />
                                            <body name="left_52" pos="0.0045 0.0282335 0" quat="0 0 0.947013 0.321197">
                                                <inertial pos="0.0045 -2.23482e-12 0.01" mass="0.00220419" diaginertia="1.54494e-07 1.51487e-07 8.96323e-08" />
                                                <joint class="finger_2" name="left_f5_j2" />
                                                <geom type="mesh" contype="0" conaffinity="0" group="1" rgba="0.792157 0.819608 0.933333 1" mesh="left_52" />
                                                <geom type="mesh" rgba="0.792157 0.819608 0.933333 1" mesh="left_52" />
                                                <body name="left_53" pos="0.0045 0.000627896 0.0187323" quat="0 0 0.527336 0.849657">
                                                    <inertial pos="-1.77189e-05 0.00926884 -3.13261e-05" quat="0.496001 0.496606 -0.502208 0.505126" mass="0.00308469" diaginertia="1.78801e-07 1.73042e-07 6.55991e-08" />
                                                    <joint class="finger_3" name="left_f5_j3" />
                                                    <geom type="mesh" contype="0" conaffinity="0" group="1" rgba="0.792157 0.819608 0.933333 1" mesh="left_53" />
                                                    <geom type="mesh" rgba="0.792157 0.819608 0.933333 1" mesh="left_53" />
                                                </body>
                                            </body>
                                        </body>
                                    </body>
                                </body>
                            </body>
                        </body>
                    </body>
                </body>
            </body>
            <body name="right_1" pos="-0.13751 -0.00843684 0.43" quat="-0.0397925 -0.0477244 0.766562 0.639157">
                <inertial pos="0.0389123 1.8308e-10 -1.73726e-10" quat="0.707107 0 0 0.707107" mass="0.450915" diaginertia="0.00114268 0.000950117 0.000939472" />
                <joint class="shoulder_1" name="right_j1"/>
               <geom class="visual" mesh="right_1" />
<!--                <geom type="mesh" rgba="0.792157 0.819608 0.933333 1" mesh="right_1" />-->
                <body name="right_2" pos="0.075 0 0" quat="0.953251 0 0.302181 0">
                    <inertial pos="0.0621308 -1.05426e-07 0.000424393" quat="-4.6643e-06 0.707687 -4.67196e-06 0.706526" mass="1.56018" diaginertia="0.00710311 0.00597557 0.00259921" />
                    <joint class="shoulder_2" name="right_j2"/>
                    <geom type="mesh" contype="0" conaffinity="0" group="1" rgba="0.792157 0.819608 0.933333 1" mesh="right_2" />
                    <geom type="mesh" rgba="0.792157 0.819608 0.933333 1" mesh="right_2" />
                    <body name="right_3" pos="0.16 0 0" quat="0.655881 -0.754864 0 0">
                        <inertial pos="0.059665 -2.32642e-09 -0.000729475" quat="0.497027 0.502955 0.502955 0.497027" mass="0.520345" diaginertia="0.00128574 0.00107323 0.000678269" />
                        <joint class="shoulder_3" name="right_j3"/>
                        <geom type="mesh" contype="0" conaffinity="0" group="1" rgba="0.792157 0.819608 0.933333 1" mesh="right_3" />
                        <geom type="mesh" rgba="0.792157 0.819608 0.933333 1" mesh="right_3" />
                        <body name="right_4" pos="0.121 0 0.037" quat="0.734316 0 0 -0.678808">
                            <inertial pos="-0.022481 0.00734431 -0.037" quat="0.572394 0.572394 0.415169 0.415169" mass="0.187003" diaginertia="0.000176801 0.00013087 0.000111406" />
                            <joint class="elbow" name="right_j4"/>
                            <geom type="mesh" contype="0" conaffinity="0" group="1" rgba="0.792157 0.819608 0.933333 1" mesh="right_4" />
                            <geom type="mesh" rgba="0.792157 0.819608 0.933333 1" mesh="right_4" />
                            <body name="right_5" pos="-0.0551325 0.0180112 -0.037" quat="0.157106 0.00610463 0.0383446 0.986818">
                                <inertial pos="0.118694 -1.97953e-08 -1.3255e-07" quat="0.499999 0.500001 0.500001 0.499999" mass="1.41911" diaginertia="0.00746362 0.00730999 0.00143555" />
                                <joint class="wrist_1" name="right_j5" />
                                <geom type="mesh" contype="0" conaffinity="0" group="1" rgba="0.792157 0.819608 0.933333 1" mesh="right_5" />
                                <geom type="mesh" rgba="0.792157 0.819608 0.933333 1" mesh="right_5" />
                                <body name="right_6" pos="0.250811 0 0.025" quat="0.998008 0 0 0.0630943">
                                    <inertial pos="0.00126437 -2.2035e-09 -0.0249938" quat="1.9496e-06 0.707125 -4.05495e-07 0.707089" mass="0.130726" diaginertia="6.86601e-05 5.37786e-05 4.85598e-05" />
                                    <joint class="wrist_2" name="right_j6"/>
                                    <geom type="mesh" contype="0" conaffinity="0" group="1" rgba="0.792157 0.819608 0.933333 1" mesh="right_6" />
                                    <geom type="mesh" rgba="0.792157 0.819608 0.933333 1" mesh="right_6" />
                                    <body name="right_7" pos="0.04 0 -0.025" quat="0.998496 -0.0548214 0 0">
                                        <inertial pos="0.0460103 2.71647e-06 -0.00209833" quat="0.471542 0.526838 0.526938 0.47162" mass="0.128554" diaginertia="0.000143165 0.00010397 5.04883e-05" />
                                        <joint class="wrist_3" name="right_j7"/>
                                        <geom type="mesh" contype="0" conaffinity="0" group="1" rgba="0.792157 0.819608 0.933333 1" mesh="right_7" />
                                        <geom type="mesh" rgba="0.792157 0.819608 0.933333 1" mesh="right_7" />
                                        <body name="right_11" pos="0.0418541 0 0.0331562" quat="0.768266 -0.572064 0.23039 0.171552">
                                            <inertial pos="0 0 0.00296384" quat="0.707107 0 0 0.707107" mass="0.00158261" diaginertia="6.47978e-08 5.66929e-08 5.56708e-08" />
                                            <joint class="thumb_1" name="right_f1_j1" />
                                            <geom type="mesh" contype="0" conaffinity="0" group="1" rgba="0.792157 0.819608 0.933333 1" mesh="right_11" />
<!--                                            <geom type="mesh" rgba="0.792157 0.819608 0.933333 1" mesh="right_11" />-->
                                            <body name="right_12" pos="0 0 0.005" quat="0.3181 0.631516 -0.3181 0.631516">
                                                <inertial pos="0.00925016 1.10221e-10 -7.20604e-11" quat="0.5 0.5 0.5 0.5" mass="0.00237615" diaginertia="1.18675e-07 1.15819e-07 1.06634e-07" />
                                                <joint class="thumb_2" name="right_f1_j2"/>
                                                <geom type="mesh" contype="0" conaffinity="0" group="1" rgba="0.792157 0.819608 0.933333 1" mesh="right_12" />
<!--                                                <geom type="mesh" rgba="0.792157 0.819608 0.933333 1" mesh="right_12" />-->
                                                <body name="right_13" pos="0.0164129 -0.000582728 0" quat="0.685816 0.172211 0.685816 -0.172211">
                                                    <inertial pos="3.30478e-08 -2.39634e-07 0.0147121" quat="0.707342 -4.59488e-06 4.59183e-06 0.706872" mass="0.00477507" diaginertia="5.13037e-07 5.06539e-07 1.11818e-07" />
                                                    <joint class="thumb_3" name="right_f1_j3" />
                                                    <geom type="mesh" contype="0" conaffinity="0" group="1" rgba="0.792157 0.819608 0.933333 1" mesh="right_13" />
                                                    <geom type="mesh" rgba="0.792157 0.819608 0.933333 1" mesh="right_13" />
                                                    <body name="right_14" pos="0.0045 0 0.0282335" quat="0 0 -0.590868 -0.806768">
                                                        <inertial pos="0.00451259 -0.000148496 0.0147394" quat="0.70472 0.00742899 -0.00610749 0.709421" mass="0.00459561" diaginertia="3.58608e-07 3.47268e-07 1.55218e-07" />
                                                        <joint class="thumb_4" name="right_f1_j4" />
                                                        <geom type="mesh" contype="0" conaffinity="0" group="1" rgba="0.792157 0.819608 0.933333 1" mesh="right_14" />
                                                        <geom type="mesh" rgba="0.792157 0.819608 0.933333 1" mesh="right_14" />
                                                    </body>
                                                </body>
                                            </body>
                                        </body>
                                        <body name="right_21" pos="0.0976114 0.000100147 0.023131" quat="0.442702 0.670057 0.32846 -0.497145">
                                            <inertial pos="3.30478e-08 0.013957 -0.00465281" quat="0.573457 0.413298 -0.413573 0.573838" mass="0.00477507" diaginertia="5.13037e-07 5.06539e-07 1.11818e-07" />
                                            <joint class="finger_1" name="right_f2_j1" />
                                            <geom type="mesh" contype="0" conaffinity="0" group="1" rgba="0.792157 0.819608 0.933333 1" mesh="right_21" />
                                            <geom type="mesh" rgba="0.792157 0.819608 0.933333 1" mesh="right_21" />
                                            <body name="right_22" pos="0.0045 0.0267842 -0.00892949" quat="0 0 0.982601 0.185727">
                                                <inertial pos="0.0045 0 0.0105" mass="0.00239726" diaginertia="1.69655e-07 1.65763e-07 9.58619e-08" />
                                                <joint class="finger_2" name="right_f2_j2" />
                                                <geom type="mesh" contype="0" conaffinity="0" group="1" rgba="0.792157 0.819608 0.933333 1" mesh="right_22" />
                                                <geom type="mesh" rgba="0.792157 0.819608 0.933333 1" mesh="right_22" />
                                                <body name="right_23" pos="0.0045 0.00104651 0.020048" quat="0 0 0.662567 0.749003">
                                                    <inertial pos="-1.84368e-05 0.00804126 -0.00695673" quat="0.63669 0.2927 -0.296036 0.649088" mass="0.00351087" diaginertia="2.40708e-07 2.34323e-07 7.61095e-08" />
                                                    <joint class="finger_3" name="right_f2_j3" />
                                                    <geom type="mesh" contype="0" conaffinity="0" group="1" rgba="0.792157 0.819608 0.933333 1" mesh="right_23" />
                                                    <geom type="mesh" rgba="0.792157 0.819608 0.933333 1" mesh="right_23" />
                                                </body>
                                            </body>
                                        </body>
                                        <body name="right_31" pos="0.100527 -0.00021688 0.00328499" quat="-0.425252 -0.564943 -0.425252 0.564943">
                                            <inertial pos="-3.56368e-07 0.014712 1.29438e-07" quat="0.499583 0.499575 -0.50042 0.50042" mass="0.0047752" diaginertia="5.13055e-07 5.06525e-07 1.11822e-07" />
                                            <joint class="finger_1" name="right_f3_j1" />
                                            <geom type="mesh" contype="0" conaffinity="0" group="1" rgba="0.792157 0.819608 0.933333 1" mesh="right_31" />
                                            <geom type="mesh" rgba="0.792157 0.819608 0.933333 1" mesh="right_31" />
                                            <body name="right_32" pos="0.0045 0.0282335 0" quat="0 0 0.987761 0.155977">
                                                <inertial pos="0.0045 0 0.0125" mass="0.00316954" diaginertia="2.43247e-07 2.35819e-07 1.2078e-07" />
                                                <joint class="finger_2" name="right_f3_j2" />
                                                <geom type="mesh" contype="0" conaffinity="0" group="1" rgba="0.792157 0.819608 0.933333 1" mesh="right_32" />
                                                <geom type="mesh" rgba="0.792157 0.819608 0.933333 1" mesh="right_32" />
                                                <body name="right_33" pos="0.0045 0.000965571 0.023966" quat="0 0 -0.398421 -0.917203">
                                                    <inertial pos="-1.95107e-05 0.0124082 -3.05611e-05" quat="0.494866 0.495556 -0.503815 0.50567" mass="0.00407938" diaginertia="3.4499e-07 3.3759e-07 9.02118e-08" />
                                                    <joint class="finger_3" name="right_f3_j3" />
                                                    <geom type="mesh" contype="0" conaffinity="0" group="1" rgba="0.792157 0.819608 0.933333 1" mesh="right_33" />
                                                    <geom type="mesh" rgba="0.792157 0.819608 0.933333 1" mesh="right_33" />
                                                </body>
                                            </body>
                                        </body>
                                        <body name="right_41" pos="0.098934 -0.000742653 -0.0158862" quat="-0.567975 -0.283066 -0.691696 0.344726">
                                            <inertial pos="3.41035e-08 0.0147121 2.45109e-07" quat="0.499839 0.499832 -0.500161 0.500168" mass="0.00477507" diaginertia="5.13037e-07 5.06539e-07 1.11818e-07" />
                                            <joint class="finger_1" name="right_f4_j1" />
                                            <geom type="mesh" contype="0" conaffinity="0" group="1" rgba="0.792157 0.819608 0.933333 1" mesh="right_41" />
                                            <geom type="mesh" rgba="0.792157 0.819608 0.933333 1" mesh="right_41" />
                                            <body name="right_42" pos="0.0045 0.0282335 0" quat="0 0 -0.970978 -0.239167">
                                                <inertial pos="0.0045 0 0.011" mass="0.00259033" diaginertia="1.86013e-07 1.81238e-07 1.02092e-07" />
                                                <joint class="finger_2" name="right_f4_j2" />
                                                <geom type="mesh" contype="0" conaffinity="0" group="1" rgba="0.792157 0.819608 0.933333 1" mesh="right_42" />
                                                <geom type="mesh" rgba="0.792157 0.819608 0.933333 1" mesh="right_42" />
                                                <body name="right_43" pos="0.0045 0.00133774 0.0215397" quat="0 0 0.164936 0.986304">
                                                    <inertial pos="-1.85188e-05 0.0106328 -3.04392e-05" quat="0.495204 0.495887 -0.503243 0.505585" mass="0.00351083" diaginertia="2.40712e-07 2.34318e-07 7.61094e-08" />
                                                    <joint class="finger_3" name="right_f4_j3" />
                                                    <geom type="mesh" contype="0" conaffinity="0" group="1" rgba="0.792157 0.819608 0.933333 1" mesh="right_43" />
                                                    <geom type="mesh" rgba="0.792157 0.819608 0.933333 1" mesh="right_43" />
                                                </body>
                                            </body>
                                        </body>
                                        <body name="right_51" pos="0.0948231 -0.000452869 -0.0322275" quat="-0.496038 -0.337491 -0.661451 0.450032">
                                            <inertial pos="3.30478e-08 0.0147121 2.39634e-07" quat="0.499837 0.49983 -0.500163 0.500169" mass="0.00477507" diaginertia="5.13037e-07 5.06539e-07 1.11818e-07" />
                                            <joint class="finger_1" name="right_f5_j1" />
                                            <geom type="mesh" contype="0" conaffinity="0" group="1" rgba="0.792157 0.819608 0.933333 1" mesh="right_51" />
                                            <geom type="mesh" rgba="0.792157 0.819608 0.933333 1" mesh="right_51" />
                                            <body name="right_52" pos="0.0045 0.0282335 0" quat="0 0 0.985455 0.169939">
                                                <inertial pos="0.0045 0 0.01" mass="0.00220419" diaginertia="1.54494e-07 1.51487e-07 8.96323e-08" />
                                                <joint class="finger_2" name="right_f5_j2" />
                                                <geom type="mesh" contype="0" conaffinity="0" group="1" rgba="0.792157 0.819608 0.933333 1" mesh="right_52" />
                                                <geom type="mesh" rgba="0.792157 0.819608 0.933333 1" mesh="right_52" />
                                                <body name="right_53" pos="0.0045 0.00061095 0.018724" quat="0 0 0.532984 0.846125">
                                                    <inertial pos="-1.78933e-05 0.00926885 -3.12861e-05" quat="0.496165 0.496774 -0.502042 0.504965" mass="0.00308472" diaginertia="1.78801e-07 1.73043e-07 6.55998e-08" />
                                                    <joint class="finger_3" name="right_f5_j3" />
                                                    <geom type="mesh" contype="0" conaffinity="0" group="1" rgba="0.792157 0.819608 0.933333 1" mesh="right_53" />
                                                    <geom type="mesh" rgba="0.792157 0.819608 0.933333 1" mesh="right_53" />
                                                </body>
                                            </body>
                                        </body>
                                    </body>
                                </body>
                            </body>
                        </body>
                    </body>
                </body>
            </body>
            <body name="neck" pos="0 0.0161746 0.515" quat="0 0 0 1">
                <inertial pos="2.88789e-08 -8.65281e-09 0.0265816" quat="0.49928 0.499347 0.500725 0.500646" mass="0.0321665" diaginertia="7.22266e-06 5.20118e-06 5.14644e-06" />
                <joint class="neck" name="body_neck"/>
                <geom type="mesh" contype="0" conaffinity="0" group="1" rgba="0.792157 0.819608 0.933333 1" mesh="neck" />
                <geom type="mesh" rgba="0.792157 0.819608 0.933333 1" mesh="neck" />
                <body name="head" pos="0.0219999 6.0166e-05 0.03" quat="0.999635 0.0269785 3.68907e-05 0.00136691">
                    <inertial pos="-0.022 0.0152892 0.0648053" quat="0.705981 0.0399037 -0.0399025 0.705979" mass="1.19735" diaginertia="0.00240376 0.00237423 0.00183049" />
                    <joint class="head" name="neck_head"/>
                    <geom type="mesh" contype="0" conaffinity="0" group="1" rgba="0.792157 0.819608 0.933333 1" mesh="head" />
                    <geom type="mesh" rgba="0.792157 0.819608 0.933333 1" mesh="head" />
                </body>
            </body>
        </body>
        <body name="ball_1" pos=".0 -.5 0.3">
            <joint armature="0" axis="1 0 0" damping="0" limited="true" name="ball_1_x" pos="0 0 0" range="-5. 5." stiffness="0" type="slide"/>
            <joint armature="0" axis="0 1 0" damping="0" limited="true" name="ball_1_y" pos="0 0 0" range="-5. 5." stiffness="0" type="slide"/>
            <joint armature="0" axis="0 0 1" damping="0" limited="true" name="ball_1_z" pos="0 0 0" range="-2. 2." stiffness="0" type="slide"/>
            <joint armature="0" damping="0.001" name="ball_1_rot" pos="0 0 0" stiffness="0" type="ball"/>
            <geom name="ball_1" pos="0 0 0" rgba="0.9 0.2 0.2 1" size=".04 .08" type="cylinder"/>
        </body>
    </worldbody>
    <actuator>
        <general class="shoulder_1" name="left_j1_T" joint="left_j1" ctrllimited="true" />
        <general class="shoulder_2" name="left_j2_T" joint="left_j2" ctrllimited="true" />
        <general class="shoulder_3" name="left_j3_T" joint="left_j3" ctrllimited="true" />
        <general class="elbow" name="left_j4_T" joint="left_j4" ctrllimited="true" />
        <general class="wrist_1" name="left_j5_T" joint="left_j5" ctrllimited="true" />
        <general class="wrist_2" name="left_j6_T" joint="left_j6" ctrllimited="true" />
        <general class="wrist_3" name="left_j7_T" joint="left_j7" ctrllimited="true" />

        <general class="thumb_1" name="left_f1_j1_T" joint="left_f1_j1" ctrllimited="true" />
        <general class="thumb_2" name="left_f1_j2_T" joint="left_f1_j2" ctrllimited="true" />
        <general class="thumb_3" name="left_f1_j3_T" joint="left_f1_j3" ctrllimited="true" />
        <general class="thumb_4" name="left_f1_j4_T" joint="left_f1_j4" ctrllimited="true" />

        <general class="finger_1" name="left_f2_j1_T" joint="left_f2_j1" ctrllimited="true" />
        <general class="finger_2" name="left_f2_j2_T" joint="left_f2_j2" ctrllimited="true" />
        <general class="finger_3" name="left_f2_j3_T" joint="left_f2_j3" ctrllimited="true" />

        <general class="finger_1" name="left_f3_j1_T" joint="left_f3_j1" ctrllimited="true" />
        <general class="finger_2" name="left_f3_j2_T" joint="left_f3_j2" ctrllimited="true" />
        <general class="finger_3" name="left_f3_j3_T" joint="left_f3_j3" ctrllimited="true" />

        <general class="finger_1" name="left_f4_j1_T" joint="left_f4_j1" ctrllimited="true" />
        <general class="finger_2" name="left_f4_j2_T" joint="left_f4_j2" ctrllimited="true" />
        <general class="finger_3" name="left_f4_j3_T" joint="left_f4_j3" ctrllimited="true" />

        <general class="finger_1" name="left_f5_j1_T" joint="left_f5_j1" ctrllimited="true" />
        <general class="finger_2" name="left_f5_j2_T" joint="left_f5_j2" ctrllimited="true" />
        <general class="finger_3" name="left_f5_j3_T" joint="left_f5_j3" ctrllimited="true" />


        <general class="thumb_1" name="right_f1_j1_T" joint="right_f1_j1" ctrllimited="true" />
        <general class="thumb_2" name="right_f1_j2_T" joint="right_f1_j2" ctrllimited="true" />
        <general class="thumb_3" name="right_f1_j3_T" joint="right_f1_j3" ctrllimited="true" />
        <general class="thumb_4" name="right_f1_j4_T" joint="right_f1_j4" ctrllimited="true" />

        <general class="finger_1" name="right_f2_j1_T" joint="right_f2_j1" ctrllimited="true" />
        <general class="finger_2" name="right_f2_j2_T" joint="right_f2_j2" ctrllimited="true" />
        <general class="finger_3" name="right_f2_j3_T" joint="right_f2_j3" ctrllimited="true" />

        <general class="finger_1" name="right_f3_j1_T" joint="right_f3_j1" ctrllimited="true" />
        <general class="finger_2" name="right_f3_j2_T" joint="right_f3_j2" ctrllimited="true" />
        <general class="finger_3" name="right_f3_j3_T" joint="right_f3_j3" ctrllimited="true" />

        <general class="finger_1" name="right_f4_j1_T" joint="right_f4_j1" ctrllimited="true" />
        <general class="finger_2" name="right_f4_j2_T" joint="right_f4_j2" ctrllimited="true" />
        <general class="finger_3" name="right_f4_j3_T" joint="right_f4_j3" ctrllimited="true" />

        <general class="finger_1" name="right_f5_j1_T" joint="right_f5_j1" ctrllimited="true" />
        <general class="finger_2" name="right_f5_j2_T" joint="right_f5_j2" ctrllimited="true" />
        <general class="finger_3" name="right_f5_j3_T" joint="right_f5_j3" ctrllimited="true" />

        <general class="shoulder_1" name="right_j1_T" joint="right_j1" ctrllimited="true" />
        <general class="shoulder_2" name="right_j2_T" joint="right_j2" ctrllimited="true" />
        <general class="shoulder_3" name="right_j3_T" joint="right_j3" ctrllimited="true" />
        <general class="elbow" name="right_j4_T" joint="right_j4" ctrllimited="true" />
        <general class="wrist_1" name="right_j5_T" joint="right_j5" ctrllimited="true" />
        <general class="wrist_2" name="right_j6_T" joint="right_j6" ctrllimited="true" />
    </actuator>
</mujoco>
