<!--<TODO: used for Humanoid(RobotModel) class to specify joint names, just include asset, worldbody and actuator, just "left hand"/>-->
<mujoco model="robot_hand_sim">
    <asset>
        <mesh name="body" file="/home/kavin/Documents/RosProjects/robot_ws/src/robot_hand_sim/meshes/body.STL" />
        <mesh name="neck" file="/home/kavin/Documents/RosProjects/robot_ws/src/robot_hand_sim/meshes/neck.STL" />
        <mesh name="head" file="/home/kavin/Documents/RosProjects/robot_ws/src/robot_hand_sim/meshes/head.STL" />
        <mesh name="left_1" file="/home/kavin/Documents/RosProjects/robot_ws/src/robot_hand_sim/meshes/left_1.STL" />
        <mesh name="left_2" file="/home/kavin/Documents/RosProjects/robot_ws/src/robot_hand_sim/meshes/left_2.STL" />
        <mesh name="left_3" file="/home/kavin/Documents/RosProjects/robot_ws/src/robot_hand_sim/meshes/left_3.STL" />
        <mesh name="left_4" file="/home/kavin/Documents/RosProjects/robot_ws/src/robot_hand_sim/meshes/left_4.STL" />
        <mesh name="left_5" file="/home/kavin/Documents/RosProjects/robot_ws/src/robot_hand_sim/meshes/left_5.STL" />
        <mesh name="left_6" file="/home/kavin/Documents/RosProjects/robot_ws/src/robot_hand_sim/meshes/left_6.STL" />
    </asset>
    <worldbody>
        <body name="body" pos="0 0 0">
            <geom type="mesh" contype="0" conaffinity="0" group="1" rgba="0.792157 0.819608 0.933333 1" mesh="body" />
            <geom type="mesh" rgba="0.792157 0.819608 0.933333 1" mesh="body" />
            <body name="left_1" pos="0.0084368 0.13751 0.43" quat="0.422014 0.509768 -0.577484 -0.478073">
                <inertial pos="-0.0389123 -8.15099e-11 4.37583e-11" quat="0.707107 0 0 0.707107" mass="0.450915" diaginertia="0.00114268 0.000950117 0.000939472" />
                <joint name="left_j1" axis="1 0 0" limited="true" range="-3.14 3.14" damping="0.001" frictionloss="0.01" />
                <geom type="mesh" contype="0" conaffinity="0" group="1" rgba="0.792157 0.819608 0.933333 1" mesh="left_1" />
                <geom type="mesh" rgba="0.792157 0.819608 0.933333 1" mesh="left_1" />
                <body name="left_2" pos="-0.075 0 0" quat="0.934135 0 -0.356919 0">
                    <inertial pos="-0.0621308 1.25597e-07 0.00042437" quat="3.21075e-06 0.706526 3.20548e-06 0.707688" mass="1.56019" diaginertia="0.00710312 0.00597558 0.00259922" />
                    <joint name="left_j2" axis="0 1 0" limited="true" range="-3.14 3.14" damping="1" frictionloss="0.01" />
                    <geom type="mesh" contype="0" conaffinity="0" group="1" rgba="0.792157 0.819608 0.933333 1" mesh="left_2" />
                    <geom type="mesh" rgba="0.792157 0.819608 0.933333 1" mesh="left_2" />
                    <body name="left_3" pos="-0.16 0 0" quat="0.792164 0.610309 0 0">
                        <inertial pos="-0.059665 2.14069e-07 -0.000729859" quat="0.502955 0.497027 0.497027 0.502955" mass="0.52034" diaginertia="0.00128574 0.00107323 0.000678269" />
                        <joint name="left_j3" axis="1 0 0" limited="true" range="-3.14 3.14" damping="1" frictionloss="0.01" />
                        <geom type="mesh" contype="0" conaffinity="0" group="1" rgba="0.792157 0.819608 0.933333 1" mesh="left_3" />
                        <geom type="mesh" rgba="0.792157 0.819608 0.933333 1" mesh="left_3" />
                        <body name="left_4" pos="-0.121 0 0.037" quat="0.854814 0 0 0.518935">
                            <inertial pos="-0.0236502 -1.38379e-09 -0.037" quat="0.5 0.5 0.5 0.5" mass="0.187003" diaginertia="0.000176801 0.00013087 0.000111406" />
                            <joint name="left_j4" axis="0 0 -1" limited="true" range="-3.14 3.14" damping="1" frictionloss="0.01" />
                            <geom type="mesh" contype="0" conaffinity="0" group="1" rgba="0.792157 0.819608 0.933333 1" mesh="left_4" />
                            <geom type="mesh" rgba="0.792157 0.819608 0.933333 1" mesh="left_4" />
                            <body name="left_5" pos="-0.058 0 -0.037" quat="0.184654 -0.982804 0 0">
                                <inertial pos="-0.118694 -2.89295e-08 1.30138e-07" quat="0.499999 0.500001 0.500001 0.499999" mass="1.41911" diaginertia="0.00746362 0.00730999 0.00143555" />
                                <joint name="left_j5" axis="1 0 0" limited="true" range="-3.14 3.14" damping="1" frictionloss="0.01"/>
                                <geom type="mesh" contype="0" conaffinity="0" group="1" rgba="0.792157 0.819608 0.933333 1" mesh="left_5" />
                                <geom type="mesh" rgba="0.792157 0.819608 0.933333 1" mesh="left_5" />
                                <body name="left_6" pos="-0.250811 0 0.025" quat="0.108969 0 0 0.994045">
                                    <inertial pos="0.00125752 -0.0001315 -0.0250062" quat="0.036822 0.70613 -0.0368186 0.706165" mass="0.130726" diaginertia="6.86601e-05 5.37786e-05 4.85598e-05" />
                                    <joint name="left_j6" axis="0 0 -1" limited="true" range="-3.14 3.14" damping="1" frictionloss="0.01" />
                                    <geom type="mesh" contype="0" conaffinity="0" group="1" rgba="0.792157 0.819608 0.933333 1" mesh="left_6" />
                                    <geom type="mesh" rgba="0.792157 0.819608 0.933333 1" mesh="left_6" />
                                    <body name="left_hand" pos="0.0397831 -0.00416024 -0.025" quat="0.0520458 -0.00170134 -0.0326275 0.99811">
                                    </body>
                                </body>
                            </body>
                        </body>
                    </body>
                </body>
            </body>
        </body>
    </worldbody>
    <actuator>
        <motor ctrllimited="true" ctrlrange="-50.0 50.0" name="left_j1_T" joint="left_j1" />
        <motor ctrllimited="true" ctrlrange="-150.0 150.0" name="left_j2_T" joint="left_j2" />
        <motor ctrllimited="true" ctrlrange="-150.0 150.0" name="left_j3_T" joint="left_j3" />
        <motor ctrllimited="true" ctrlrange="-50.0 50.0" name="left_j4_T" joint="left_j4" />
        <motor ctrllimited="true" ctrlrange="-150.0 150.0" name="left_j5_T" joint="left_j5" />
        <motor ctrllimited="true" ctrlrange="-28.0 28.0" name="left_j6_T" joint="left_j6" />
<!--        <motor ctrllimited="true" ctrlrange="-8.0 8.0" name="left_j7_T" joint="left_j7" />-->
    </actuator>
</mujoco>
